<!-- YAML
added: v0.1.21
changes:
  - version: v10.2.0
    pr-url: https://github.com/nodejs/node/pull/20485
    description: The `error` parameter can be an object containing regular
                 expressions now.
  - version: v9.9.0
    pr-url: https://github.com/nodejs/node/pull/17584
    description: The `error` parameter can now be an object as well.
  - version: v4.2.0
    pr-url: https://github.com/nodejs/node/pull/3276
    description: The `error` parameter can now be an arrow function.
-->
* `fn` {Function}
* `error` {RegExp|Function|Object|Error}
* `message` {string}

Expects the function `fn` to throw an error.

If specified, `error` can be a [`Class`][], [`RegExp`][], a validation function,
a validation object where each property will be tested for strict deep equality,
or an instance of error where each property will be tested for strict deep
equality including the non-enumerable `message` and `name` properties. When
using an object, it is also possible to use a regular expression, when
validating against a string property. See below for examples.

If specified, `message` will be appended to the message provided by the
`AssertionError` if the `fn` call fails to throw or in case the error validation
fails.

Custom validation object/error instance:

```js
const err = new TypeError('Wrong value');
err.code = 404;
err.foo = 'bar';
err.info = {
  nested: true,
  baz: 'text'
};
err.reg = /abc/i;

assert.throws(
  () => {
    throw err;
  },
  {
    name: 'TypeError',
    message: 'Wrong value',
    info: {
      nested: true,
      baz: 'text'
    }
    // Note that only properties on the validation object will be tested for.
    // Using nested objects requires all properties to be present. Otherwise
    // the validation is going to fail.
  }
);

// Using regular expressions to validate error properties:
assert.throws(
  () => {
    throw err;
  },
  {
    // The `name` and `message` properties are strings and using regular
    // expressions on those will match against the string. If they fail, an
    // error is thrown.
    name: /^TypeError$/,
    message: /Wrong/,
    foo: 'bar',
    info: {
      nested: true,
      // It is not possible to use regular expressions for nested properties!
      baz: 'text'
    },
    // The `reg` property contains a regular expression and only if the
    // validation object contains an identical regular expression, it is going
    // to pass.
    reg: /abc/i
  }
);

// Fails due to the different `message` and `name` properties:
assert.throws(
  () => {
    const otherErr = new Error('Not found');
    otherErr.code = 404;
    throw otherErr;
  },
  err // This tests for `message`, `name` and `code`.
);
```

Validate instanceof using constructor:

```js
assert.throws(
  () => {
    throw new Error('Wrong value');
  },
  Error
);
```

Validate error message using [`RegExp`][]:

Using a regular expression runs `.toString` on the error object, and will
therefore also include the error name.

```js
assert.throws(
  () => {
    throw new Error('Wrong value');
  },
  /^Error: Wrong value$/
);
```

Custom error validation:

```js
assert.throws(
  () => {
    throw new Error('Wrong value');
  },
  function(err) {
    if ((err instanceof Error) && /value/.test(err)) {
      return true;
    }
  },
  'unexpected error'
);
```

Note that `error` cannot be a string. If a string is provided as the second
argument, then `error` is assumed to be omitted and the string will be used for
`message` instead. This can lead to easy-to-miss mistakes. Using the same
message as the thrown error message is going to result in an
`ERR_AMBIGUOUS_ARGUMENT` error. Please read the example below carefully if using
a string as the second argument gets considered:

<!-- eslint-disable no-restricted-syntax -->
```js
function throwingFirst() {
  throw new Error('First');
}
function throwingSecond() {
  throw new Error('Second');
}
function notThrowing() {}

// The second argument is a string and the input function threw an Error.
// The first case will not throw as it does not match for the error message
// thrown by the input function!
assert.throws(throwingFirst, 'Second');
// In the next example the message has no benefit over the message from the
// error and since it is not clear if the user intended to actually match
// against the error message, Node.js thrown an `ERR_AMBIGUOUS_ARGUMENT` error.
assert.throws(throwingSecond, 'Second');
// Throws an error:
// TypeError [ERR_AMBIGUOUS_ARGUMENT]

// The string is only used (as message) in case the function does not throw:
assert.throws(notThrowing, 'Second');
// AssertionError [ERR_ASSERTION]: Missing expected exception: Second

// If it was intended to match for the error message do this instead:
assert.throws(throwingSecond, /Second$/);
// Does not throw because the error messages match.
assert.throws(throwingFirst, /Second$/);
// Throws an error:
// Error: First
//     at throwingFirst (repl:2:9)
```

Due to the confusing notation, it is recommended not to use a string as the
second argument. This might lead to difficult-to-spot errors.






























