<!-- YAML
added: v10.0.0
-->
* `block` {Function|Promise}
* `error` {RegExp|Function|Object|Error}
* `message` {any}

Awaits the `block` promise or, if `block` is a function, immediately calls the
function and awaits the returned promise to complete. It will then check that
the promise is rejected.

If `block` is a function and it throws an error synchronously,
`assert.rejects()` will return a rejected `Promise` with that error. If the
function does not return a promise, `assert.rejects()` will return a rejected
`Promise` with an [`ERR_INVALID_RETURN_VALUE`][] error. In both cases the error
handler is skipped.

Besides the async nature to await the completion behaves identically to
[`assert.throws()`][].

If specified, `error` can be a [`Class`][], [`RegExp`][], a validation function,
an object where each property will be tested for, or an instance of error where
each property will be tested for including the non-enumerable `message` and
`name` properties.

If specified, `message` will be the message provided by the `AssertionError` if
the block fails to reject.

```js
(async () => {
  await assert.rejects(
    async () => {
      throw new TypeError('Wrong value');
    },
    {
      name: 'TypeError',
      message: 'Wrong value'
    }
  );
})();
```

```js
assert.rejects(
  Promise.reject(new Error('Wrong value')),
  Error
).then(() => {
  // ...
});
```

Note that `error` cannot be a string. If a string is provided as the second
argument, then `error` is assumed to be omitted and the string will be used for
`message` instead. This can lead to easy-to-miss mistakes. Please read the
example in [`assert.throws()`][] carefully if using a string as the second
argument gets considered.

